Workbook

Sheet ملخص المناديب
A1: شيت المتابعة اليومية للمناديب — Smou Lifts (Odoo CRM)
A2: الفترة: 01/09/2026 حتى 30/09/2026 | البيانات متاحة فعلياً حتى 2026-09-30 | المصدر: crm.lead | آخر تحديث: 01/10/2026
A4: المندوب | B4: عدد الفرص | C4: اسم العميل مكتوب | D4: Plot Number | E4: الاستشاري | F4: المقاول | G4: Tags | H4: مرفقات | I4: Source | J4: ملاحظات | K4: نسبة الاكتمال % | L4: عدد الأكشنات | M4: أكشنات تفصيلية | N4: أكشنات مختصرة | O4: نسبة التفصيل % | P4: الملاحظة العامة على المندوب
A5: Abdullhadi AlHariri | B5: =COUNTIF('تفاصيل الفرص'!$D$2:$D$372,$A5) -> 51 | C5: =COUNTIFS('تفاصيل الفرص'!$D$2:$D$372,$A5,'تفاصيل الفرص'!$I$2:$I$372,"نعم") -> 51 | D5: =COUNTIFS('تفاصيل الفرص'!$D$2:$D$372,$A5,'تفاصيل الفرص'!$K$2:$K$372,"نعم") -> 5 | E5: =COUNTIFS('تفاصيل الفرص'!$D$2:$D$372,$A5,'تفاصيل الفرص'!$M$2:$M$372,"نعم") -> 25 | F5: =COUNTIFS('تفاصيل الفرص'!$D$2:$D$372,$A5,'تفاصيل الفرص'!$O$2:$O$372,"نعم") -> 24 | G5: =COUNTIFS('تفاصيل الفرص'!$D$2:$D$372,$A5,'تفاصيل الفرص'!$Q$2:$Q$372,"نعم") -> 47 | H5: =COUNTIFS('تفاصيل الفرص'!$D$2:$D$372,$A5,'تفاصيل الفرص'!$S$2:$S$372,"نعم") -> 0 | I5: =COUNTIFS('تفاصيل الفرص'!$D$2:$D$372,$A5,'تفاصيل الفرص'!$U$2:$U$372,"نعم") -> 0 | J5: =COUNTIFS('تفاصيل الفرص'!$D$2:$D$372,$A5,'تفاصيل الفرص'!$W$2:$W$372,"نعم") -> 5 | K5: =IF($B5=0,0,SUM(C5:J5)/($B5*8)) -> 0.38480392 | L5: =COUNTIF('سجل الأكشنات'!$D$2:$D$933,$A5) -> 132 | M5: =COUNTIFS('سجل الأكشنات'!$D$2:$D$933,$A5,'سجل الأكشنات'!$H$2:$H$933,"تفصيلي") -> 125 | N5: =L5-M5 -> 7 | O5: =IF($L5=0,0,M5/L5) -> 0.9469697 | P5: لا يكتب إطلاقاً: مرفقات، Source (في كل الـ51 فرصة) · كثيراً ما يترك فارغاً: Plot Number (46/51)، ملاحظات (46/51)، المقاول (27/51)، الاستشاري (26/51) · الأكشنات: 132 أكشن منها 7 مختصر/بدون نص
A6: Ahmed AlDinary | B6: =COUNTIF('تفاصيل الفرص'!$D$2:$D$372,$A6) -> 47 | C6: =COUNTIFS('تفاصيل الفرص'!$D$2:$D$372,$A6,'تفاصيل الفرص'!$I$2:$I$372,"نعم") -> 4 | D6: =COUNTIFS('تفاصيل الفرص'!$D$2:$D$372,$A6,'تفاصيل الفرص'!$K$2:$K$372,"نعم") -> 2 | E6: =COUNTIFS('تفاصيل الفرص'!$D$2:$D$372,$A6,'تفاصيل الفرص'!$M$2:$M$372,"نعم") -> 4 | F6: =COUNTIFS('تفاصيل الفرص'!$D$2:$D$372,$A6,'تفاصيل الفرص'!$O$2:$O$372,"نعم") -> 4 | G6: =COUNTIFS('تفاصيل الفرص'!$D$2:$D$372,$A6,'تفاصيل الفرص'!$Q$2:$Q$372,"نعم") -> 5 | H6: =COUNTIFS('تفاصيل الفرص'!$D$2:$D$372,$A6,'تفاصيل الفرص'!$S$2:$S$372,"نعم") -> 0 | I6: =COUNTIFS('تفاصيل الفرص'!$D$2:$D$372,$A6,'تفاصيل الفرص'!$U$2:$U$372,"نعم") -> 5 | J6: =COUNTIFS('تفاصيل الفرص'!$D$2:$D$372,$A6,'تفاصيل الفرص'!$W$2:$W$372,"نعم") -> 0 | K6: =IF($B6=0,0,SUM(C6:J6)/($B6*8)) -> 0.063829787 | L6: =COUNTIF('سجل الأكشنات'!$D$2:$D$933,$A6) -> 124 | M6: =COUNTIFS('سجل الأكشنات'!$D$2:$D$933,$A6,'سجل الأكشنات'!$H$2:$H$933,"تفصيلي") -> 107 | N6: =L6-M6 -> 17 | O6: =IF($L6=0,0,M6/L6) -> 0.86290323 | P6: لا يكتب إطلاقاً: مرفقات، ملاحظات (في كل الـ47 فرصة) · كثيراً ما يترك فارغاً: Plot Number (45/47)، اسم العميل (43/47)، الاستشاري (43/47)، المقاول (43/47)، Tags (42/47)، Source (42/47) · الأكشنات: 124 أكشن منها 17 مختصر/بدون نص
A7: Ahmed Alattar | B7: =COUNTIF('تفاصيل الفرص'!$D$2:$D$372,$A7) -> 30 | C7: =COUNTIFS('تفاصيل الفرص'!$D$2:$D$372,$A7,'تفاصيل الفرص'!$I$2:$I$372,"نعم") -> 30 | D7: =COUNTIFS('تفاصيل الفرص'!$D$2:$D$372,$A7,'تفاصيل الفرص'!$K$2:$K$372,"نعم") -> 0 | E7: =COUNTIFS('تفاصيل الفرص'!$D$2:$D$372,$A7,'تفاصيل الفرص'!$M$2:$M$372,"نعم") -> 19 | F7: =COUNTIFS('تفاصيل الفرص'!$D$2:$D$372,$A7,'تفاصيل الفرص'!$O$2:$O$372,"نعم") -> 18 | G7: =COUNTIFS('تفاصيل الفرص'!$D$2:$D$372,$A7,'تفاصيل الفرص'!$Q$2:$Q$372,"نعم") -> 29 | H7: =COUNTIFS('تفاصيل الفرص'!$D$2:$D$372,$A7,'تفاصيل الفرص'!$S$2:$S$372,"نعم") -> 0 | I7: =COUNTIFS('تفاصيل الفرص'!$D$2:$D$372,$A7,'تفاصيل الفرص'!$U$2:$U$372,"نعم") -> 9 | J7: =COUNTIFS('تفاصيل الفرص'!$D$2:$D$372,$A7,'تفاصيل الفرص'!$W$2:$W$372,"نعم") -> 4 | K7: =IF($B7=0,0,SUM(C7:J7)/($B7*8)) -> 0.45416667 | L7: =COUNTIF('سجل الأكشنات'!$D$2:$D$933,$A7) -> 73 | M7: =COUNTIFS('سجل الأكشنات'!$D$2:$D$933,$A7,'سجل الأكشنات'!$H$2:$H$933,"تفصيلي") -> 48 | N7: =L7-M7 -> 25 | O7: =IF($L7=0,0,M7/L7) -> 0.65753425 | P7: لا يكتب إطلاقاً: Plot Number، مرفقات (في كل الـ30 فرصة) · كثيراً ما يترك فارغاً: ملاحظات (26/30)، Source (21/30) · الأكشنات: 73 أكشن منها 25 مختصر/بدون نص
A8: Ahmed Salah | B8: =COUNTIF('تفاصيل الفرص'!$D$2:$D$372,$A8) -> 23 | C8: =COUNTIFS('تفاصيل الفرص'!$D$2:$D$372,$A8,'تفاصيل الفرص'!$I$2:$I$372,"نعم") -> 2 | D8: =COUNTIFS('تفاصيل الفرص'!$D$2:$D$372,$A8,'تفاصيل الفرص'!$K$2:$K$372,"نعم") -> 6 | E8: =COUNTIFS('تفاصيل الفرص'!$D$2:$D$372,$A8,'تفاصيل الفرص'!$M$2:$M$372,"نعم") -> 13 | F8: =COUNTIFS('تفاصيل الفرص'!$D$2:$D$372,$A8,'تفاصيل الفرص'!$O$2:$O$372,"نعم") -> 12 | G8: =COUNTIFS('تفاصيل الفرص'!$D$2:$D$372,$A8,'تفاصيل الفرص'!$Q$2:$Q$372,"نعم") -> 12 | H8: =COUNTIFS('تفاصيل الفرص'!$D$2:$D$372,$A8,'تفاصيل الفرص'!$S$2:$S$372,"نعم") -> 0 | I8: =COUNTIFS('تفاصيل الفرص'!$D$2:$D$372,$A8,'تفاصيل الفرص'!$U$2:$U$372,"نعم") -> 0 | J8: =COUNTIFS('تفاصيل الفرص'!$D$2:$D$372,$A8,'تفاصيل الفرص'!$W$2:$W$372,"نعم") -> 0 | K8: =IF($B8=0,0,SUM(C8:J8)/($B8*8)) -> 0.24456522 | L8: =COUNTIF('سجل الأكشنات'!$D$2:$D$933,$A8) -> 80 | M8: =COUNTIFS('سجل الأكشنات'!$D$2:$D$933,$A8,'سجل الأكشنات'!$H$2:$H$933,"تفصيلي") -> 78 | N8: =L8-M8 -> 2 | O8: =IF($L8=0,0,M8/L8) -> 0.975 | P8: لا يكتب إطلاقاً: مرفقات، Source، ملاحظات (في كل الـ23 فرصة) · كثيراً ما يترك فارغاً: اسم العميل (21/23)، Plot Number (17/23) · الأكشنات: 80 أكشن منها 2 مختصر/بدون نص
A9: Hossam Radi | B9: =COUNTIF('تفاصيل الفرص'!$D$2:$D$372,$A9) -> 0 | C9: =COUNTIFS('تفاصيل الفرص'!$D$2:$D$372,$A9,'تفاصيل الفرص'!$I$2:$I$372,"نعم") -> 0 | D9: =COUNTIFS('تفاصيل الفرص'!$D$2:$D$372,$A9,'تفاصيل الفرص'!$K$2:$K$372,"نعم") -> 0 | E9: =COUNTIFS('تفاصيل الفرص'!$D$2:$D$372,$A9,'تفاصيل الفرص'!$M$2:$M$372,"نعم") -> 0 | F9: =COUNTIFS('تفاصيل الفرص'!$D$2:$D$372,$A9,'تفاصيل الفرص'!$O$2:$O$372,"نعم") -> 0 | G9: =COUNTIFS('تفاصيل الفرص'!$D$2:$D$372,$A9,'تفاصيل الفرص'!$Q$2:$Q$372,"نعم") -> 0 | H9: =COUNTIFS('تفاصيل الفرص'!$D$2:$D$372,$A9,'تفاصيل الفرص'!$S$2:$S$372,"نعم") -> 0 | I9: =COUNTIFS('تفاصيل الفرص'!$D$2:$D$372,$A9,'تفاصيل الفرص'!$U$2:$U$372,"نعم") -> 0 | J9: =COUNTIFS('تفاصيل الفرص'!$D$2:$D$372,$A9,'تفاصيل الفرص'!$W$2:$W$372,"نعم") -> 0 | K9: =IF($B9=0,0,SUM(C9:J9)/($B9*8)) -> 0 | L9: =COUNTIF('سجل الأكشنات'!$D$2:$D$933,$A9) -> 16 | M9: =COUNTIFS('سجل الأكشنات'!$D$2:$D$933,$A9,'سجل الأكشنات'!$H$2:$H$933,"تفصيلي") -> 16 | N9: =L9-M9 -> 0 | O9: =IF($L9=0,0,M9/L9) -> 1 | P9: لم ينشئ أي فرصة في الفترة · الأكشنات: 16 أكشن كلها مكتوبة بتفاصيل ✔
A10: Mohamed Saqr | B10: =COUNTIF('تفاصيل الفرص'!$D$2:$D$372,$A10) -> 13 | C10: =COUNTIFS('تفاصيل الفرص'!$D$2:$D$372,$A10,'تفاصيل الفرص'!$I$2:$I$372,"نعم") -> 0 | D10: =COUNTIFS('تفاصيل الفرص'!$D$2:$D$372,$A10,'تفاصيل الفرص'!$K$2:$K$372,"نعم") -> 0 | E10: =COUNTIFS('تفاصيل الفرص'!$D$2:$D$372,$A10,'تفاصيل الفرص'!$M$2:$M$372,"نعم") -> 3 | F10: =COUNTIFS('تفاصيل الفرص'!$D$2:$D$372,$A10,'تفاصيل الفرص'!$O$2:$O$372,"نعم") -> 2 | G10: =COUNTIFS('تفاصيل الفرص'!$D$2:$D$372,$A10,'تفاصيل الفرص'!$Q$2:$Q$372,"نعم") -> 2 | H10: =COUNTIFS('تفاصيل الفرص'!$D$2:$D$372,$A10,'تفاصيل الفرص'!$S$2:$S$372,"نعم") -> 0 | I10: =COUNTIFS('تفاصيل الفرص'!$D$2:$D$372,$A10,'تفاصيل الفرص'!$U$2:$U$372,"نعم") -> 1 | J10: =COUNTIFS('تفاصيل الفرص'!$D$2:$D$372,$A10,'تفاصيل الفرص'!$W$2:$W$372,"نعم") -> 0 | K10: =IF($B10=0,0,SUM(C10:J10)/($B10*8)) -> 0.076923077 | L10: =COUNTIF('سجل الأكشنات'!$D$2:$D$933,$A10) -> 73 | M10: =COUNTIFS('سجل الأكشنات'!$D$2:$D$933,$A10,'سجل الأكشنات'!$H$2:$H$933,"تفصيلي") -> 71 | N10: =L10-M10 -> 2 | O10: =IF($L10=0,0,M10/L10) -> 0.97260274 | P10: لا يكتب إطلاقاً: اسم العميل، Plot Number، مرفقات، ملاحظات (في كل الـ13 فرصة) · كثيراً ما يترك فارغاً: Source (12/13)، المقاول (11/13)، Tags (11/13)، الاستشاري (10/13) · الأكشنات: 73 أكشن منها 2 مختصر/بدون نص
A11: Mohammed Jamal | B11: =COUNTIF('تفاصيل الفرص'!$D$2:$D$372,$A11) -> 97 | C11: =COUNTIFS('تفاصيل الفرص'!$D$2:$D$372,$A11,'تفاصيل الفرص'!$I$2:$I$372,"نعم") -> 96 | D11: =COUNTIFS('تفاصيل الفرص'!$D$2:$D$372,$A11,'تفاصيل الفرص'!$K$2:$K$372,"نعم") -> 1 | E11: =COUNTIFS('تفاصيل الفرص'!$D$2:$D$372,$A11,'تفاصيل الفرص'!$M$2:$M$372,"نعم") -> 21 | F11: =COUNTIFS('تفاصيل الفرص'!$D$2:$D$372,$A11,'تفاصيل الفرص'!$O$2:$O$372,"نعم") -> 4 | G11: =COUNTIFS('تفاصيل الفرص'!$D$2:$D$372,$A11,'تفاصيل الفرص'!$Q$2:$Q$372,"نعم") -> 92 | H11: =COUNTIFS('تفاصيل الفرص'!$D$2:$D$372,$A11,'تفاصيل الفرص'!$S$2:$S$372,"نعم") -> 0 | I11: =COUNTIFS('تفاصيل الفرص'!$D$2:$D$372,$A11,'تفاصيل الفرص'!$U$2:$U$372,"نعم") -> 83 | J11: =COUNTIFS('تفاصيل الفرص'!$D$2:$D$372,$A11,'تفاصيل الفرص'!$W$2:$W$372,"نعم") -> 0 | K11: =IF($B11=0,0,SUM(C11:J11)/($B11*8)) -> 0.38273196 | L11: =COUNTIF('سجل الأكشنات'!$D$2:$D$933,$A11) -> 101 | M11: =COUNTIFS('سجل الأكشنات'!$D$2:$D$933,$A11,'سجل الأكشنات'!$H$2:$H$933,"تفصيلي") -> 88 | N11: =L11-M11 -> 13 | O11: =IF($L11=0,0,M11/L11) -> 0.87128713 | P11: لا يكتب إطلاقاً: مرفقات، ملاحظات (في كل الـ97 فرصة) · كثيراً ما يترك فارغاً: Plot Number (96/97)، المقاول (93/97)، الاستشاري (76/97) · الأكشنات: 101 أكشن منها 13 مختصر/بدون نص
A12: Ramy Moussa | B12: =COUNTIF('تفاصيل الفرص'!$D$2:$D$372,$A12) -> 34 | C12: =COUNTIFS('تفاصيل الفرص'!$D$2:$D$372,$A12,'تفاصيل الفرص'!$I$2:$I$372,"نعم") -> 34 | D12: =COUNTIFS('تفاصيل الفرص'!$D$2:$D$372,$A12,'تفاصيل الفرص'!$K$2:$K$372,"نعم") -> 3 | E12: =COUNTIFS('تفاصيل الفرص'!$D$2:$D$372,$A12,'تفاصيل الفرص'!$M$2:$M$372,"نعم") -> 11 | F12: =COUNTIFS('تفاصيل الفرص'!$D$2:$D$372,$A12,'تفاصيل الفرص'!$O$2:$O$372,"نعم") -> 9 | G12: =COUNTIFS('تفاصيل الفرص'!$D$2:$D$372,$A12,'تفاصيل الفرص'!$Q$2:$Q$372,"نعم") -> 7 | H12: =COUNTIFS('تفاصيل الفرص'!$D$2:$D$372,$A12,'تفاصيل الفرص'!$S$2:$S$372,"نعم") -> 0 | I12: =COUNTIFS('تفاصيل الفرص'!$D$2:$D$372,$A12,'تفاصيل الفرص'!$U$2:$U$372,"نعم") -> 7 | J12: =COUNTIFS('تفاصيل الفرص'!$D$2:$D$372,$A12,'تفاصيل الفرص'!$W$2:$W$372,"نعم") -> 0 | K12: =IF($B12=0,0,SUM(C12:J12)/($B12*8)) -> 0.26102941 | L12: =COUNTIF('سجل الأكشنات'!$D$2:$D$933,$A12) -> 95 | M12: =COUNTIFS('سجل الأكشنات'!$D$2:$D$933,$A12,'سجل الأكشنات'!$H$2:$H$933,"تفصيلي") -> 70 | N12: =L12-M12 -> 25 | O12: =IF($L12=0,0,M12/L12) -> 0.73684211 | P12: لا يكتب إطلاقاً: مرفقات، ملاحظات (في كل الـ34 فرصة) · كثيراً ما يترك فارغاً: Plot Number (31/34)، Tags (27/34)، Source (27/34)، المقاول (25/34)، الاستشاري (23/34) · الأكشنات: 95 أكشن منها 25 مختصر/بدون نص
A13: Yossry Fayez | B13: =COUNTIF('تفاصيل الفرص'!$D$2:$D$372,$A13) -> 76 | C13: =COUNTIFS('تفاصيل الفرص'!$D$2:$D$372,$A13,'تفاصيل الفرص'!$I$2:$I$372,"نعم") -> 75 | D13: =COUNTIFS('تفاصيل الفرص'!$D$2:$D$372,$A13,'تفاصيل الفرص'!$K$2:$K$372,"نعم") -> 2 | E13: =COUNTIFS('تفاصيل الفرص'!$D$2:$D$372,$A13,'تفاصيل الفرص'!$M$2:$M$372,"نعم") -> 70 | F13: =COUNTIFS('تفاصيل الفرص'!$D$2:$D$372,$A13,'تفاصيل الفرص'!$O$2:$O$372,"نعم") -> 71 | G13: =COUNTIFS('تفاصيل الفرص'!$D$2:$D$372,$A13,'تفاصيل الفرص'!$Q$2:$Q$372,"نعم") -> 75 | H13: =COUNTIFS('تفاصيل الفرص'!$D$2:$D$372,$A13,'تفاصيل الفرص'!$S$2:$S$372,"نعم") -> 0 | I13: =COUNTIFS('تفاصيل الفرص'!$D$2:$D$372,$A13,'تفاصيل الفرص'!$U$2:$U$372,"نعم") -> 76 | J13: =COUNTIFS('تفاصيل الفرص'!$D$2:$D$372,$A13,'تفاصيل الفرص'!$W$2:$W$372,"نعم") -> 0 | K13: =IF($B13=0,0,SUM(C13:J13)/($B13*8)) -> 0.60690789 | L13: =COUNTIF('سجل الأكشنات'!$D$2:$D$933,$A13) -> 238 | M13: =COUNTIFS('سجل الأكشنات'!$D$2:$D$933,$A13,'سجل الأكشنات'!$H$2:$H$933,"تفصيلي") -> 213 | N13: =L13-M13 -> 25 | O13: =IF($L13=0,0,M13/L13) -> 0.89495798 | P13: لا يكتب إطلاقاً: مرفقات، ملاحظات (في كل الـ76 فرصة) · كثيراً ما يترك فارغاً: Plot Number (74/76) · الأكشنات: 238 أكشن منها 25 مختصر/بدون نص
A14: الإجمالي | B14: =SUM(B5:B13) -> 371 | C14: =SUM(C5:C13) -> 292 | D14: =SUM(D5:D13) -> 19 | E14: =SUM(E5:E13) -> 166 | F14: =SUM(F5:F13) -> 144 | G14: =SUM(G5:G13) -> 269 | H14: =SUM(H5:H13) -> 0 | I14: =SUM(I5:I13) -> 181 | J14: =SUM(J5:J13) -> 9 | K14: =IF($B14=0,0,SUM(C14:J14)/($B14*8)) -> 0.3638814 | L14: =SUM(L5:L13) -> 932 | M14: =SUM(M5:M13) -> 816 | N14: =SUM(N5:N13) -> 116 | O14: =IF($L14=0,0,M14/L14) -> 0.87553648
A16: ملاحظات على المنهجية:
A17: • «عدد الفرص» = الفرص (crm.lead) التي أنشأها المندوب في الفترة، بتوقيت الإمارات (UTC+4).
A18: • أعمدة الفحص تَعُدّ الفرص التي بها الخانة ممتلئة فعلياً (نعم) — التفاصيل سطراً بسطر في تاب «تفاصيل الفرص».
A19: • «نسبة الاكتمال %» = مجموع الخانات الممتلئة ÷ (عدد الفرص × 8 خانات مطلوبة).
A20: • «عدد الأكشنات» = الأنشطة المنفّذة (Activity done) + الملاحظات المسجّلة على الفرص خلال الفترة.
A21: • «تفصيلي» = نص الأكشن 40 حرفاً فأكثر · «مختصر» = أقل من 40 حرفاً أو فارغ.
A22: • البيانات مسحوبة من الأودو بتاريخ 01/10/2026 — آخر يوم به نشاط مسجّل هو 2026-09-30.
A23: • المناديب المستبعدون من الشيت: Sayed Samak.

Sheet متابعة يومية
A1: المتابعة اليومية لكل مندوب — 01/09/2026 إلى 30/09/2026
A3: اليوم | B3: التاريخ | C3: المندوب | D3: عدد الفرص | E3: الفرص المكتملة 100% | F3: الأكشنات | G3: أكشنات تفصيلية | H3: أكشنات مختصرة | I3: حالة اليوم
A4: الثلاثاء | B4: 2026-09-01 | C4: Abdullhadi AlHariri | D4: =COUNTIFS('تفاصيل الفرص'!$B$2:$B$372,$B4,'تفاصيل الفرص'!$D$2:$D$372,$C4) -> 0 | E4: =COUNTIFS('تفاصيل الفرص'!$B$2:$B$372,$B4,'تفاصيل الفرص'!$D$2:$D$372,$C4,'تفاصيل الفرص'!$X$2:$X$372,0) -> 0 | F4: =COUNTIFS('سجل الأكشنات'!$B$2:$B$933,$B4,'سجل الأكشنات'!$D$2:$D$933,$C4) -> 3 | G4: =COUNTIFS('سجل الأكشنات'!$B$2:$B$933,$B4,'سجل الأكشنات'!$D$2:$D$933,$C4,'سجل الأكشنات'!$H$2:$H$933,"تفصيلي") -> 3 | H4: =F4-G4 -> 0 | I4: =IF($B4>"2026-09-30","لا توجد بيانات بعد",IF(AND(D4=0,F4=0),"بدون نشاط","نشِط")) -> نشِط
A5: الثلاثاء | B5: 2026-09-01 | C5: Ahmed AlDinary | D5: =COUNTIFS('تفاصيل الفرص'!$B$2:$B$372,$B5,'تفاصيل الفرص'!$D$2:$D$372,$C5) -> 0 | E5: =COUNTIFS('تفاصيل الفرص'!$B$2:$B$372,$B5,'تفاصيل الفرص'!$D$2:$D$372,$C5,'تفاصيل الفرص'!$X$2:$X$372,0) -> 0 | F5: =COUNTIFS('سجل الأكشنات'!$B$2:$B$933,$B5,'سجل الأكشنات'!$D$2:$D$933,$C5) -> 0 | G5: =COUNTIFS('سجل الأكشنات'!$B$2:$B$933,$B5,'سجل الأكشنات'!$D$2:$D$933,$C5,'سجل الأكشنات'!$H$2:$H$933,"تفصيلي") -> 0 | H5: =F5-G5 -> 0 | I5: =IF($B5>"2026-09-30","لا توجد بيانات بعد",IF(AND(D5=0,F5=0),"بدون نشاط","نشِط")) -> بدون نشاط
A6: الثلاثاء | B6: 2026-09-01 | C6: Ahmed Alattar | D6: =COUNTIFS('تفاصيل الفرص'!$B$2:$B$372,$B6,'تفاصيل الفرص'!$D$2:$D$372,$C6) -> 1 | E6: =COUNTIFS('تفاصيل الفرص'!$B$2:$B$372,$B6,'تفاصيل الفرص'!$D$2:$D$372,$C6,'تفاصيل الفرص'!$X$2:$X$372,0) -> 0 | F6: =COUNTIFS('سجل الأكشنات'!$B$2:$B$933,$B6,'سجل الأكشنات'!$D$2:$D$933,$C6) -> 5 | G6: =COUNTIFS('سجل الأكشنات'!$B$2:$B$933,$B6,'سجل الأكشنات'!$D$2:$D$933,$C6,'سجل الأكشنات'!$H$2:$H$933,"تفصيلي") -> 4 | H6: =F6-G6 -> 1 | I6: =IF($B6>"2026-09-30","لا توجد بيانات بعد",IF(AND(D6=0,F6=0),"بدون نشاط","نشِط")) -> نشِط
A7: الثلاثاء | B7: 2026-09-01 | C7: Ahmed Salah | D7: =COUNTIFS('تفاصيل الفرص'!$B$2:$B$372,$B7,'تفاصيل الفرص'!$D$2:$D$372,$C7) -> 0 | E7: =COUNTIFS('تفاصيل الفرص'!$B$2:$B$372,$B7,'تفاصيل الفرص'!$D$2:$D$372,$C7,'تفاصيل الفرص'!$X$2:$X$372,0) -> 0 | F7: =COUNTIFS('سجل الأكشنات'!$B$2:$B$933,$B7,'سجل الأكشنات'!$D$2:$D$933,$C7) -> 3 | G7: =COUNTIFS('سجل الأكشنات'!$B$2:$B$933,$B7,'سجل الأكشنات'!$D$2:$D$933,$C7,'سجل الأكشنات'!$H$2:$H$933,"تفصيلي") -> 3 | H7: =F7-G7 -> 0 | I7: =IF($B7>"2026-09-30","لا توجد بيانات بعد",IF(AND(D7=0,F7=0),"بدون نشاط","نشِط")) -> نشِط
A8: الثلاثاء | B8: 2026-09-01 | C8: Hossam Radi | D8: =COUNTIFS('تفاصيل الفرص'!$B$2:$B$372,$B8,'تفاصيل الفرص'!$D$2:$D$372,$C8) -> 0 | E8: =COUNTIFS('تفاصيل الفرص'!$B$2:$B$372,$B8,'تفاصيل الفرص'!$D$2:$D$372,$C8,'تفاصيل الفرص'!$X$2:$X$372,0) -> 0 | F8: =COUNTIFS('سجل الأكشنات'!$B$2:$B$933,$B8,'سجل الأكشنات'!$D$2:$D$933,$C8) -> 12 | G8: =COUNTIFS('سجل الأكشنات'!$B$2:$B$933,$B8,'سجل الأكشنات'!$D$2:$D$933,$C8,'سجل الأكشنات'!$H$2:$H$933,"تفصيلي") -> 12 | H8: =F8-G8 -> 0 | I8: =IF($B8>"2026-09-30","لا توجد بيانات بعد",IF(AND(D8=0,F8=0),"بدون نشاط","نشِط")) -> نشِط
A9: الثلاثاء | B9: 2026-09-01 | C9: Mohamed Saqr | D9: =COUNTIFS('تفاصيل الفرص'!$B$2:$B$372,$B9,'تفاصيل الفرص'!$D$2:$D$372,$C9) -> 0 | E9: =COUNTIFS('تفاصيل الفرص'!$B$2:$B$372,$B9,'تفاصيل الفرص'!$D$2:$D$372,$C9,'تفاصيل الفرص'!$X$2:$X$372,0) -> 0 | F9: =COUNTIFS('سجل الأكشنات'!$B$2:$B$933,$B9,'سجل الأكشنات'!$D$2:$D$933,$C9) -> 0 | G9: =COUNTIFS('سجل الأكشنات'!$B$2:$B$933,$B9,'سجل الأكشنات'!$D$2:$D$933,$C9,'سجل الأكشنات'!$H$2:$H$933,"تفصيلي") -> 0 | H9: =F9-G9 -> 0 | I9: =IF($B9>"2026-09-30","لا توجد بيانات بعد",IF(AND(D9=0,F9=0),"بدون نشاط","نشِط")) -> بدون نشاط
A10: الثلاثاء | B10: 2026-09-01 | C10: Mohammed Jamal | D10: =COUNTIFS('تفاصيل الفرص'!$B$2:$B$372,$B10,'تفاصيل الفرص'!$D$2:$D$372,$C10) -> 1 | E10: =COUNTIFS('تفاصيل الفرص'!$B$2:$B$372,$B10,'تفاصيل الفرص'!$D$2:$D$372,$C10,'تفاصيل الفرص'!$X$2:$X$372,0) -> 0 | F10: =COUNTIFS('سجل الأكشنات'!$B$2:$B$933,$B10,'سجل الأكشنات'!$D$2:$D$933,$C10) -> 1 | G10: =COUNTIFS('سجل الأكشنات'!$B$2:$B$933,$B10,'سجل الأكشنات'!$D$2:$D$933,$C10,'سجل الأكشنات'!$H$2:$H$933,"تفصيلي") -> 0 | H10: =F10-G10 -> 1 | I10: =IF($B10>"2026-09-30","لا توجد بيانات بعد",IF(AND(D10=0,F10=0),"بدون نشاط","نشِط")) -> نشِط
A11: الثلاثاء | B11: 2026-09-01 | C11: Ramy Moussa | D11: =COUNTIFS('تفاصيل الفرص'!$B$2:$B$372,$B11,'تفاصيل الفرص'!$D$2:$D$372,$C11) -> 0 | E11: =COUNTIFS('تفاصيل الفرص'!$B$2:$B$372,$B11,'تفاصيل الفرص'!$D$2:$D$372,$C11,'تفاصيل الفرص'!$X$2:$X$372,0) -> 0 | F11: =COUNTIFS('سجل الأكشنات'!$B$2:$B$933,$B11,'سجل الأكشنات'!$D$2:$D$933,$C11) -> 1 | G11: =COUNTIFS('سجل الأكشنات'!$B$2:$B$933,$B11,'سجل الأكشنات'!$D$2:$D$933,$C11,'سجل الأكشنات'!$H$2:$H$933,"تفصيلي") -> 1 | H11: =F11-G11 -> 0 | I11: =IF($B11>"2026-09-30","لا توجد بيانات بعد",IF(AND(D11=0,F11=0),"بدون نشاط","نشِط")) -> نشِط
A12: الثلاثاء | B12: 2026-09-01 | C12: Yossry Fayez | D12: =COUNTIFS('تفاصيل الفرص'!$B$2:$B$372,$B12,'تفاصيل الفرص'!$D$2:$D$372,$C12) -> 2 | E12: =COUNTIFS('تفاصيل الفرص'!$B$2:$B$372,$B12,'تفاصيل الفرص'!$D$2:$D$372,$C12,'تفاصيل الفرص'!$X$2:$X$372,0) -> 0 | F12: =COUNTIFS('سجل الأكشنات'!$B$2:$B$933,$B12,'سجل الأكشنات'!$D$2:$D$933,$C12) -> 8 | G12: =COUNTIFS('سجل الأكشنات'!$B$2:$B$933,$B12,'سجل الأكشنات'!$D$2:$D$933,$C12,'سجل الأكشنات'!$H$2:$H$933,"تفصيلي") -> 8 | H12: =F12-G12 -> 0 | I12: =IF($B12>"2026-09-30","لا توجد بيانات بعد",IF(AND(D12=0,F12=0),"بدون نشاط","نشِط")) -> نشِط
A13: الأربعاء | B13: 2026-09-02 | C13: Abdullhadi AlHariri | D13: =COUNTIFS('تفاصيل الفرص'!$B$2:$B$372,$B13,'تفاصيل الفرص'!$D$2:$D$372,$C13) -> 3 | E13: =COUNTIFS('تفاصيل الفرص'!$B$2:$B$372,$B13,'تفاصيل الفرص'!$D$2:$D$372,$C13,'تفاصيل الفرص'!$X$2:$X$372,0) -> 0 | F13: =COUNTIFS('سجل الأكشنات'!$B$2:$B$933,$B13,'سجل الأكشنات'!$D$2:$D$933,$C13) -> 5 | G13: =COUNTIFS('سجل الأكشنات'!$B$2:$B$933,$B13,'سجل الأكشنات'!$D$2:$D$933,$C13,'سجل الأكشنات'!$H$2:$H$933,"تفصيلي") -> 5 | H13: =F13-G13 -> 0 | I13: =IF($B13>"2026-09-30","لا توجد بيانات بعد",IF(AND(D13=0,F13=0),"بدون نشاط","نشِط")) -> نشِط
A14: الأربعاء | B14: 2026-09-02 | C14: Ahmed AlDinary | D14: =COUNTIFS('تفاصيل الفرص'!$B$2:$B$372,$B14,'تفاصيل الفرص'!$D$2:$D$372,$C14) -> 0 | E14: =COUNTIFS('تفاصيل الفرص'!$B$2:$B$372,$B14,'تفاصيل الفرص'!$D$2:$D$372,$C14,'تفاصيل الفرص'!$X$2:$X$372,0) -> 0 | F14: =COUNTIFS('سجل الأكشنات'!$B$2:$B$933,$B14,'سجل الأكشنات'!$D$2:$D$933,$C14) -> 0 | G14: =COUNTIFS('سجل الأكشنات'!$B$2:$B$933,$B14,'سجل الأكشنات'!$D$2:$D$933,$C14,'سجل الأكشنات'!$H$2:$H$933,"تفصيلي") -> 0 | H14: =F14-G14 -> 0 | I14: =IF($B14>"2026-09-30","لا توجد بيانات بعد",IF(AND(D14=0,F14=0),"بدون نشاط","نشِط")) -> بدون نشاط
A15: الأربعاء | B15: 2026-09-02 | C15: Ahmed Alattar | D15: =COUNTIFS('تفاصيل الفرص'!$B$2:$B$372,$B15,'تفاصيل الفرص'!$D$2:$D$372,$C15) -> 1 | E15: =COUNTIFS('تفاصيل الفرص'!$B$2:$B$372,$B15,'تفاصيل الفرص'!$D$2:$D$372,$C15,'تفاصيل الفرص'!$X$2:$X$372,0) -> 0 | F15: =COUNTIFS('سجل الأكشنات'!$B$2:$B$933,$B15,'سجل الأكشنات'!$D$2:$D$933,$C15) -> 2 | G15: =COUNTIFS('سجل الأكشنات'!$B$2:$B$933,$B15,'سجل الأكشنات'!$D$2:$D$933,$C15,'سجل الأكشنات'!$H$2:$H$933,"تفصيلي") -> 2 | H15: =F15-G15 -> 0 | I15: =IF($B15>"2026-09-30","لا توجد بيانات بعد",IF(AND(D15=0,F15=0),"بدون نشاط","نشِط")) -> نشِط
... A273: الأربعاء | B273: 2026-09-30 | C273: Yossry Fayez | D273: =COUNTIFS('تفاصيل الفرص'!$B$2:$B$372,$B273,'تفاصيل الفرص'!$D$2:$D$372,$C273) -> 0 | E273: =COUNTIFS('تفاصيل الفرص'!$B$2:$B$372,$B273,'تفاصيل الفرص'!$D$2:$D$372,$C273,'تفاصيل الفرص'!$X$2:$X$372,0) -> 0 | F273: =COUNTIFS('سجل الأكشنات'!$B$2:$B$933,$B273,'سجل الأكشنات'!$D$2:$D$933,$C273) -> 1 | G273: =COUNTIFS('سجل الأكشنات'!$B$2:$B$933,$B273,'سجل الأكشنات'!$D$2:$D$933,$C273,'سجل الأكشنات'!$H$2:$H$933,"تفصيلي") -> 1 | H273: =F273-G273 -> 0 | I273: =IF($B273>"2026-09-30","لا توجد بيانات بعد",IF(AND(D273=0,F273=0),"بدون نشاط","نشِط")) -> نشِط

Sheet الملاحظات وتكرارها
A1: الملاحظات المتكررة ومدى تكرارها
A2: إجمالي الفرص المفحوصة: 371 | إجمالي الأكشنات المفحوصة: 932 | الفترة 01/09 – 30/09/2026
A4: أولاً: الملاحظات على الفرص — أي خانة تُترك فارغة وكم مرة تكررت
A5: الملاحظة (نص التعليق) | B5: الخانة | C5: عدد الفرص المتأثرة | D5: نسبة التكرار من الفرص | E5: عدد المناديب المتأثرين | F5: أكثر مندوب تكراراً | G5: Abdullhadi AlHariri | H5: Ahmed AlDinary | I5: Ahmed Alattar | J5: Ahmed Salah | K5: Mohamed Saqr | L5: Mohammed Jamal | M5: Ramy Moussa | N5: Yossry Fayez
A6: المندوب لم يكتب «اسم العميل» في الفرصة | B6: اسم العميل | C6: =COUNTIF('تفاصيل الفرص'!$I$2:$I$372,"لا") -> 79 | D6: =IF(371=0,0,C6/371) -> 0.21293801 | E6: 5 | F6: Ahmed AlDinary (43) | G6: =COUNTIFS('تفاصيل الفرص'!$D$2:$D$372,G$5,'تفاصيل الفرص'!$I$2:$I$372,"لا") -> 0 | H6: =COUNTIFS('تفاصيل الفرص'!$D$2:$D$372,H$5,'تفاصيل الفرص'!$I$2:$I$372,"لا") -> 43 | I6: =COUNTIFS('تفاصيل الفرص'!$D$2:$D$372,I$5,'تفاصيل الفرص'!$I$2:$I$372,"لا") -> 0 | J6: =COUNTIFS('تفاصيل الفرص'!$D$2:$D$372,J$5,'تفاصيل الفرص'!$I$2:$I$372,"لا") -> 21 | K6: =COUNTIFS('تفاصيل الفرص'!$D$2:$D$372,K$5,'تفاصيل الفرص'!$I$2:$I$372,"لا") -> 13 | L6: =COUNTIFS('تفاصيل الفرص'!$D$2:$D$372,L$5,'تفاصيل الفرص'!$I$2:$I$372,"لا") -> 1 | M6: =COUNTIFS('تفاصيل الفرص'!$D$2:$D$372,M$5,'تفاصيل الفرص'!$I$2:$I$372,"لا") -> 0 | N6: =COUNTIFS('تفاصيل الفرص'!$D$2:$D$372,N$5,'تفاصيل الفرص'!$I$2:$I$372,"لا") -> 1
A7: المندوب لم يكتب «Plot Number» في الفرصة | B7: Plot Number | C7: =COUNTIF('تفاصيل الفرص'!$K$2:$K$372,"لا") -> 352 | D7: =IF(371=0,0,C7/371) -> 0.94878706 | E7: 8 | F7: Mohammed Jamal (96) | G7: =COUNTIFS('تفاصيل الفرص'!$D$2:$D$372,G$5,'تفاصيل الفرص'!$K$2:$K$372,"لا") -> 46 | H7: =COUNTIFS('تفاصيل الفرص'!$D$2:$D$372,H$5,'تفاصيل الفرص'!$K$2:$K$372,"لا") -> 45 | I7: =COUNTIFS('تفاصيل الفرص'!$D$2:$D$372,I$5,'تفاصيل الفرص'!$K$2:$K$372,"لا") -> 30 | J7: =COUNTIFS('تفاصيل الفرص'!$D$2:$D$372,J$5,'تفاصيل الفرص'!$K$2:$K$372,"لا") -> 17 | K7: =COUNTIFS('تفاصيل الفرص'!$D$2:$D$372,K$5,'تفاصيل الفرص'!$K$2:$K$372,"لا") -> 13 | L7: =COUNTIFS('تفاصيل الفرص'!$D$2:$D$372,L$5,'تفاصيل الفرص'!$K$2:$K$372,"لا") -> 96 | M7: =COUNTIFS('تفاصيل الفرص'!$D$2:$D$372,M$5,'تفاصيل الفرص'!$K$2:$K$372,"لا") -> 31 | N7: =COUNTIFS('تفاصيل الفرص'!$D$2:$D$372,N$5,'تفاصيل الفرص'!$K$2:$K$372,"لا") -> 74
A8: المندوب لم يكتب «الاستشاري» في الفرصة | B8: الاستشاري | C8: =COUNTIF('تفاصيل الفرص'!$M$2:$M$372,"لا") -> 205 | D8: =IF(371=0,0,C8/371) -> 0.55256065 | E8: 8 | F8: Mohammed Jamal (76) | G8: =COUNTIFS('تفاصيل الفرص'!$D$2:$D$372,G$5,'تفاصيل الفرص'!$M$2:$M$372,"لا") -> 26 | H8: =COUNTIFS('تفاصيل الفرص'!$D$2:$D$372,H$5,'تفاصيل الفرص'!$M$2:$M$372,"لا") -> 43 | I8: =COUNTIFS('تفاصيل الفرص'!$D$2:$D$372,I$5,'تفاصيل الفرص'!$M$2:$M$372,"لا") -> 11 | J8: =COUNTIFS('تفاصيل الفرص'!$D$2:$D$372,J$5,'تفاصيل الفرص'!$M$2:$M$372,"لا") -> 10 | K8: =COUNTIFS('تفاصيل الفرص'!$D$2:$D$372,K$5,'تفاصيل الفرص'!$M$2:$M$372,"لا") -> 10 | L8: =COUNTIFS('تفاصيل الفرص'!$D$2:$D$372,L$5,'تفاصيل الفرص'!$M$2:$M$372,"لا") -> 76 | M8: =COUNTIFS('تفاصيل الفرص'!$D$2:$D$372,M$5,'تفاصيل الفرص'!$M$2:$M$372,"لا") -> 23 | N8: =COUNTIFS('تفاصيل الفرص'!$D$2:$D$372,N$5,'تفاصيل الفرص'!$M$2:$M$372,"لا") -> 6
A9: المندوب لم يكتب «المقاول» في الفرصة | B9: المقاول | C9: =COUNTIF('تفاصيل الفرص'!$O$2:$O$372,"لا") -> 227 | D9: =IF(371=0,0,C9/371) -> 0.61185984 | E9: 8 | F9: Mohammed Jamal (93) | G9: =COUNTIFS('تفاصيل الفرص'!$D$2:$D$372,G$5,'تفاصيل الفرص'!$O$2:$O$372,"لا") -> 27 | H9: =COUNTIFS('تفاصيل الفرص'!$D$2:$D$372,H$5,'تفاصيل الفرص'!$O$2:$O$372,"لا") -> 43 | I9: =COUNTIFS('تفاصيل الفرص'!$D$2:$D$372,I$5,'تفاصيل الفرص'!$O$2:$O$372,"لا") -> 12 | J9: =COUNTIFS('تفاصيل الفرص'!$D$2:$D$372,J$5,'تفاصيل الفرص'!$O$2:$O$372,"لا") -> 11 | K9: =COUNTIFS('تفاصيل الفرص'!$D$2:$D$372,K$5,'تفاصيل الفرص'!$O$2:$O$372,"لا") -> 11 | L9: =COUNTIFS('تفاصيل الفرص'!$D$2:$D$372,L$5,'تفاصيل الفرص'!$O$2:$O$372,"لا") -> 93 | M9: =COUNTIFS('تفاصيل الفرص'!$D$2:$D$372,M$5,'تفاصيل الفرص'!$O$2:$O$372,"لا") -> 25 | N9: =COUNTIFS('تفاصيل الفرص'!$D$2:$D$372,N$5,'تفاصيل الفرص'!$O$2:$O$372,"لا") -> 5
A10: المندوب لم يكتب «Tags» في الفرصة | B10: Tags | C10: =COUNTIF('تفاصيل الفرص'!$Q$2:$Q$372,"لا") -> 102 | D10: =IF(371=0,0,C10/371) -> 0.27493261 | E10: 8 | F10: Ahmed AlDinary (42) | G10: =COUNTIFS('تفاصيل الفرص'!$D$2:$D$372,G$5,'تفاصيل الفرص'!$Q$2:$Q$372,"لا") -> 4 | H10: =COUNTIFS('تفاصيل الفرص'!$D$2:$D$372,H$5,'تفاصيل الفرص'!$Q$2:$Q$372,"لا") -> 42 | I10: =COUNTIFS('تفاصيل الفرص'!$D$2:$D$372,I$5,'تفاصيل الفرص'!$Q$2:$Q$372,"لا") -> 1 | J10: =COUNTIFS('تفاصيل الفرص'!$D$2:$D$372,J$5,'تفاصيل الفرص'!$Q$2:$Q$372,"لا") -> 11 | K10: =COUNTIFS('تفاصيل الفرص'!$D$2:$D$372,K$5,'تفاصيل الفرص'!$Q$2:$Q$372,"لا") -> 11 | L10: =COUNTIFS('تفاصيل الفرص'!$D$2:$D$372,L$5,'تفاصيل الفرص'!$Q$2:$Q$372,"لا") -> 5 | M10: =COUNTIFS('تفاصيل الفرص'!$D$2:$D$372,M$5,'تفاصيل الفرص'!$Q$2:$Q$372,"لا") -> 27 | N10: =COUNTIFS('تفاصيل الفرص'!$D$2:$D$372,N$5,'تفاصيل الفرص'!$Q$2:$Q$372,"لا") -> 1
A11: المندوب لم يكتب «مرفقات» في الفرصة | B11: مرفقات | C11: =COUNTIF('تفاصيل الفرص'!$S$2:$S$372,"لا") -> 371 | D11: =IF(371=0,0,C11/371) -> 1 | E11: 8 | F11: Mohammed Jamal (97) | G11: =COUNTIFS('تفاصيل الفرص'!$D$2:$D$372,G$5,'تفاصيل الفرص'!$S$2:$S$372,"لا") -> 51 | H11: =COUNTIFS('تفاصيل الفرص'!$D$2:$D$372,H$5,'تفاصيل الفرص'!$S$2:$S$372,"لا") -> 47 | I11: =COUNTIFS('تفاصيل الفرص'!$D$2:$D$372,I$5,'تفاصيل الفرص'!$S$2:$S$372,"لا") -> 30 | J11: =COUNTIFS('تفاصيل الفرص'!$D$2:$D$372,J$5,'تفاصيل الفرص'!$S$2:$S$372,"لا") -> 23 | K11: =COUNTIFS('تفاصيل الفرص'!$D$2:$D$372,K$5,'تفاصيل الفرص'!$S$2:$S$372,"لا") -> 13 | L11: =COUNTIFS('تفاصيل الفرص'!$D$2:$D$372,L$5,'تفاصيل الفرص'!$S$2:$S$372,"لا") -> 97 | M11: =COUNTIFS('تفاصيل الفرص'!$D$2:$D$372,M$5,'تفاصيل الفرص'!$S$2:$S$372,"لا") -> 34 | N11: =COUNTIFS('تفاصيل الفرص'!$D$2:$D$372,N$5,'تفاصيل الفرص'!$S$2:$S$372,"لا") -> 76
A12: المندوب لم يكتب «Source» في الفرصة | B12: Source | C12: =COUNTIF('تفاصيل الفرص'!$U$2:$U$372,"لا") -> 190 | D12: =IF(371=0,0,C12/371) -> 0.51212938 | E12: 7 | F12: Abdullhadi AlHariri (51) | G12: =COUNTIFS('تفاصيل الفرص'!$D$2:$D$372,G$5,'تفاصيل الفرص'!$U$2:$U$372,"لا") -> 51 | H12: =COUNTIFS('تفاصيل الفرص'!$D$2:$D$372,H$5,'تفاصيل الفرص'!$U$2:$U$372,"لا") -> 42 | I12: =COUNTIFS('تفاصيل الفرص'!$D$2:$D$372,I$5,'تفاصيل الفرص'!$U$2:$U$372,"لا") -> 21 | J12: =COUNTIFS('تفاصيل الفرص'!$D$2:$D$372,J$5,'تفاصيل الفرص'!$U$2:$U$372,"لا") -> 23 | K12: =COUNTIFS('تفاصيل الفرص'!$D$2:$D$372,K$5,'تفاصيل الفرص'!$U$2:$U$372,"لا") -> 12 | L12: =COUNTIFS('تفاصيل الفرص'!$D$2:$D$372,L$5,'تفاصيل الفرص'!$U$2:$U$372,"لا") -> 14 | M12: =COUNTIFS('تفاصيل الفرص'!$D$2:$D$372,M$5,'تفاصيل الفرص'!$U$2:$U$372,"لا") -> 27 | N12: =COUNTIFS('تفاصيل الفرص'!$D$2:$D$372,N$5,'تفاصيل الفرص'!$U$2:$U$372,"لا") -> 0
A13: المندوب لم يكتب «ملاحظات» في الفرصة | B13: ملاحظات | C13: =COUNTIF('تفاصيل الفرص'!$W$2:$W$372,"لا") -> 362 | D13: =IF(371=0,0,C13/371) -> 0.97574124 | E13: 8 | F13: Mohammed Jamal (97) | G13: =COUNTIFS('تفاصيل الفرص'!$D$2:$D$372,G$5,'تفاصيل الفرص'!$W$2:$W$372,"لا") -> 46 | H13: =COUNTIFS('تفاصيل الفرص'!$D$2:$D$372,H$5,'تفاصيل الفرص'!$W$2:$W$372,"لا") -> 47 | I13: =COUNTIFS('تفاصيل الفرص'!$D$2:$D$372,I$5,'تفاصيل الفرص'!$W$2:$W$372,"لا") -> 26 | J13: =COUNTIFS('تفاصيل الفرص'!$D$2:$D$372,J$5,'تفاصيل الفرص'!$W$2:$W$372,"لا") -> 23 | K13: =COUNTIFS('تفاصيل الفرص'!$D$2:$D$372,K$5,'تفاصيل الفرص'!$W$2:$W$372,"لا") -> 13 | L13: =COUNTIFS('تفاصيل الفرص'!$D$2:$D$372,L$5,'تفاصيل الفرص'!$W$2:$W$372,"لا") -> 97 | M13: =COUNTIFS('تفاصيل الفرص'!$D$2:$D$372,M$5,'تفاصيل الفرص'!$W$2:$W$372,"لا") -> 34 | N13: =COUNTIFS('تفاصيل الفرص'!$D$2:$D$372,N$5,'تفاصيل الفرص'!$W$2:$W$372,"لا") -> 76
A16: ثانياً: أكثر أنماط النقص تكراراً (نفس مجموعة الخانات الناقصة معاً)
A17: نمط النقص (الخانات الناقصة معاً) | B17: عدد الفرص | C17: النسبة من الفرص
A18: ناقص: Plot Number، مرفقات، ملاحظات | B18: 74 | C18: =IF(371=0,0,B18/371) -> 0.19946092
A19: ناقص: Plot Number، الاستشاري، المقاول، مرفقات، ملاحظات | B19: 67 | C19: =IF(371=0,0,B19/371) -> 0.18059299
A20: ناقص: اسم العميل، Plot Number، الاستشاري، المقاول، Tags، مرفقات، Source، ملاحظات | B20: 56 | C20: =IF(371=0,0,B20/371) -> 0.1509434
A21: ناقص: Plot Number، الاستشاري، المقاول، Tags، مرفقات، Source، ملاحظات | B21: 30 | C21: =IF(371=0,0,B21/371) -> 0.080862534
A22: ناقص: Plot Number، المقاول، مرفقات، ملاحظات | B22: 21 | C22: =IF(371=0,0,B22/371) -> 0.056603774
A23: ناقص: Plot Number، المقاول، مرفقات، Source، ملاحظات | B23: 21 | C23: =IF(371=0,0,B23/371) -> 0.056603774
A24: ناقص: Plot Number، الاستشاري، مرفقات، Source، ملاحظات | B24: 19 | C24: =IF(371=0,0,B24/371) -> 0.051212938
A25: ناقص: Plot Number، الاستشاري، المقاول، مرفقات، Source، ملاحظات | B25: 15 | C25: =IF(371=0,0,B25/371) -> 0.040431267
A26: ناقص: Plot Number، مرفقات، Source، ملاحظات | B26: 10 | C26: =IF(371=0,0,B26/371) -> 0.026954178
A27: ناقص: Plot Number، الاستشاري، مرفقات، ملاحظات | B27: 7 | C27: =IF(371=0,0,B27/371) -> 0.018867925
A28: ناقص: مرفقات، ملاحظات | B28: 5 | C28: =IF(371=0,0,B28/371) -> 0.013477089
A29: ناقص: مرفقات، Source، ملاحظات | B29: 4 | C29: =IF(371=0,0,B29/371) -> 0.010781671
A32: ثالثاً: الملاحظات على الأكشنات وكم مرة تكررت
A33: الملاحظة على الأكشن | B33: عدد الأكشنات | C33: النسبة من الأكشنات | D33: Abdullhadi AlHariri | E33: Ahmed AlDinary | F33: Ahmed Alattar | G33: Ahmed Salah | H33: Mohamed Saqr | I33: Mohammed Jamal | J33: Ramy Moussa | K33: Yossry Fayez
A34: أكشن مكتوب بتفاصيل كافية ✔ | B34: =COUNTIF('سجل الأكشنات'!$J$2:$J$933,$A34) -> 816 | C34: =IF(932=0,0,B34/932) -> 0.87553648 | D34: =COUNTIFS('سجل الأكشنات'!$D$2:$D$933,D$33,'سجل الأكشنات'!$J$2:$J$933,$A34) -> 125 | E34: =COUNTIFS('سجل الأكشنات'!$D$2:$D$933,E$33,'سجل الأكشنات'!$J$2:$J$933,$A34) -> 107 | F34: =COUNTIFS('سجل الأكشنات'!$D$2:$D$933,F$33,'سجل الأكشنات'!$J$2:$J$933,$A34) -> 48 | G34: =COUNTIFS('سجل الأكشنات'!$D$2:$D$933,G$33,'سجل الأكشنات'!$J$2:$J$933,$A34) -> 78 | H34: =COUNTIFS('سجل الأكشنات'!$D$2:$D$933,H$33,'سجل الأكشنات'!$J$2:$J$933,$A34) -> 71 | I34: =COUNTIFS('سجل الأكشنات'!$D$2:$D$933,I$33,'سجل الأكشنات'!$J$2:$J$933,$A34) -> 88 | J34: =COUNTIFS('سجل الأكشنات'!$D$2:$D$933,J$33,'سجل الأكشنات'!$J$2:$J$933,$A34) -> 70 | K34: =COUNTIFS('سجل الأكشنات'!$D$2:$D$933,K$33,'سجل الأكشنات'!$J$2:$J$933,$A34) -> 213
A35: أكشن مختصر — لا يوضّح نتيجة التواصل أو الخطوة التالية | B35: =COUNTIF('سجل الأكشنات'!$J$2:$J$933,$A35) -> 57 | C35: =IF(932=0,0,B35/932) -> 0.061158798 | D35: =COUNTIFS('سجل الأكشنات'!$D$2:$D$933,D$33,'سجل الأكشنات'!$J$2:$J$933,$A35) -> 6 | E35: =COUNTIFS('سجل الأكشنات'!$D$2:$D$933,E$33,'سجل الأكشنات'!$J$2:$J$933,$A35) -> 3 | F35: =COUNTIFS('سجل الأكشنات'!$D$2:$D$933,F$33,'سجل الأكشنات'!$J$2:$J$933,$A35) -> 22 | G35: =COUNTIFS('سجل الأكشنات'!$D$2:$D$933,G$33,'سجل الأكشنات'!$J$2:$J$933,$A35) -> 1 | H35: =COUNTIFS('سجل الأكشنات'!$D$2:$D$933,H$33,'سجل الأكشنات'!$J$2:$J$933,$A35) -> 2 | I35: =COUNTIFS('سجل الأكشنات'!$D$2:$D$933,I$33,'سجل الأكشنات'!$J$2:$J$933,$A35) -> 7 | J35: =COUNTIFS('سجل الأكشنات'!$D$2:$D$933,J$33,'سجل الأكشنات'!$J$2:$J$933,$A35) -> 16 | K35: =COUNTIFS('سجل الأكشنات'!$D$2:$D$933,K$33,'سجل الأكشنات'!$J$2:$J$933,$A35) -> 0
A36: أكشن مختصر جداً — النص تلقائي/عام بدون تفاصيل الزيارة أو نتيجتها | B36: =COUNTIF('سجل الأكشنات'!$J$2:$J$933,$A36) -> 42 | C36: =IF(932=0,0,B36/932) -> 0.045064378 | D36: =COUNTIFS('سجل الأكشنات'!$D$2:$D$933,D$33,'سجل الأكشنات'!$J$2:$J$933,$A36) -> 0 | E36: =COUNTIFS('سجل الأكشنات'!$D$2:$D$933,E$33,'سجل الأكشنات'!$J$2:$J$933,$A36) -> 8 | F36: =COUNTIFS('سجل الأكشنات'!$D$2:$D$933,F$33,'سجل الأكشنات'!$J$2:$J$933,$A36) -> 3 | G36: =COUNTIFS('سجل الأكشنات'!$D$2:$D$933,G$33,'سجل الأكشنات'!$J$2:$J$933,$A36) -> 1 | H36: =COUNTIFS('سجل الأكشنات'!$D$2:$D$933,H$33,'سجل الأكشنات'!$J$2:$J$933,$A36) -> 0 | I36: =COUNTIFS('سجل الأكشنات'!$D$2:$D$933,I$33,'سجل الأكشنات'!$J$2:$J$933,$A36) -> 6 | J36: =COUNTIFS('سجل الأكشنات'!$D$2:$D$933,J$33,'سجل الأكشنات'!$J$2:$J$933,$A36) -> 9 | K36: =COUNTIFS('سجل الأكشنات'!$D$2:$D$933,K$33,'سجل الأكشنات'!$J$2:$J$933,$A36) -> 15
A37: ملاحظة مسجّلة بدون أي نص | B37: =COUNTIF('سجل الأكشنات'!$J$2:$J$933,$A37) -> 17 | C37: =IF(932=0,0,B37/932) -> 0.018240343 | D37: =COUNTIFS('سجل الأكشنات'!$D$2:$D$933,D$33,'سجل الأكشنات'!$J$2:$J$933,$A37) -> 1 | E37: =COUNTIFS('سجل الأكشنات'!$D$2:$D$933,E$33,'سجل الأكشنات'!$J$2:$J$933,$A37) -> 6 | F37: =COUNTIFS('سجل الأكشنات'!$D$2:$D$933,F$33,'سجل الأكشنات'!$J$2:$J$933,$A37) -> 0 | G37: =COUNTIFS('سجل الأكشنات'!$D$2:$D$933,G$33,'سجل الأكشنات'!$J$2:$J$933,$A37) -> 0 | H37: =COUNTIFS('سجل الأكشنات'!$D$2:$D$933,H$33,'سجل الأكشنات'!$J$2:$J$933,$A37) -> 0 | I37: =COUNTIFS('سجل الأكشنات'!$D$2:$D$933,I$33,'سجل الأكشنات'!$J$2:$J$933,$A37) -> 0 | J37: =COUNTIFS('سجل الأكشنات'!$D$2:$D$933,J$33,'سجل الأكشنات'!$J$2:$J$933,$A37) -> 0 | K37: =COUNTIFS('سجل الأكشنات'!$D$2:$D$933,K$33,'سجل الأكشنات'!$J$2:$J$933,$A37) -> 10
A40: رابعاً: الملاحظة المجمّعة لكل مندوب
A41: المندوب | B41: عدد الفرص | C41: عدد الأكشنات | D41: الملاحظة
A42: Abdullhadi AlHariri | B42: 51 | C42: 132
A43: Ahmed AlDinary | B43: 47 | C43: 124
A44: Ahmed Alattar | B44: 30 | C44: 73
A45: Ahmed Salah | B45: 23 | C45: 80
A46: Hossam Radi | B46: 0 | C46: 16
A47: Mohamed Saqr | B47: 13 | C47: 73
...

Sheet تفاصيل الفرص
A1: رقم الفرصة | B1: التاريخ | C1: الوقت | D1: المندوب | E1: الفريق | F1: المرحلة | G1: اسم الفرصة | H1: اسم العميل | I1: اسم العميل ✓ | J1: Plot Number | K1: Plot Number ✓ | L1: الاستشاري | M1: الاستشاري ✓ | N1: المقاول | O1: المقاول ✓ | P1: Tags | Q1: Tags ✓ | R1: عدد المرفقات | S1: مرفقات ✓ | T1: Source | U1: Source ✓ | V1: طول الملاحظات | W1: ملاحظات ✓ | X1: عدد النواقص | Y1: الملاحظة
A2: 43054 | B2: 2026-09-01 | C2: 09:55 | D2: Yossry Fayez | E2: Abu Dhabi, and Al Ain 1 | F2: Quotation | G2: مكتب تربل زيرو للاستشارات الهندسية- جيان | H2: مكتب تربل زيرو للاستشارات الهندسية | I2: نعم | K2: لا | L2: تربل زيرو للاستشارات الهندسية | M2: نعم | N2: جيانكم للمقاولات | O2: نعم | P2: تكييف, مصعد, مواقع | Q2: نعم | R2: 0 | S2: لا | T2: مواقع | U2: نعم | V2: 0 | W2: لا | X2: 3 | Y2: المندوب لم يكتب: Plot Number، مرفقات، ملاحظات (3 خانة ناقصة)
A3: 43060 | B3: 2026-09-01 | C3: 11:08 | D3: Yossry Fayez | E3: Abu Dhabi, and Al Ain 1 | F3: Clients | G3: السلمانية للمقاولات والعقارات | H3: السلمانية للمقاولات والعقارات | I3: نعم | K3: لا | L3: مكتب فراس للاستشارات الهندسية | M3: نعم | N3: السلمانية للمقاولات والعقارات | O3: نعم | P3: مصعد, مواقع | Q3: نعم | R3: 0 | S3: لا | T3: مواقع | U3: نعم | V3: 0 | W3: لا | X3: 3 | Y3: المندوب لم يكتب: Plot Number، مرفقات، ملاحظات (3 خانة ناقصة)
A4: 43066 | B4: 2026-09-01 | C4: 17:20 | D4: Mohammed Jamal | E4: Abu Dhabi, and Al Ain | F4: Clients | G4: الدوام اليوم's opportunity | H4: الدوام اليوم | I4: نعم | K4: لا | M4: لا | O4: لا | Q4: لا | R4: 0 | S4: لا | U4: لا | V4: 0 | W4: لا | X4: 7 | Y4: المندوب لم يكتب: Plot Number، الاستشاري، المقاول، Tags، مرفقات، Source، ملاحظات (7 خانة ناقصة)
A5: 43067 | B5: 2026-09-01 | C5: 21:02 | D5: Ahmed Alattar | E5: ADMIN | F5: Clients | G5: مكتب اوتاد للاستشارات والمقاولات's oppor | H5: مكتب اوتاد للاستشارات والمقاولات | I5: نعم | K5: لا | L5: مكتب اوتاد للاستشارات الهندسية | M5: نعم | N5: اوتاد للمقاولات | O5: نعم | P5: مكتب استشارات, مكتب مقاولات | Q5: نعم | R5: 0 | S5: لا | U5: لا | V5: 0 | W5: لا | X5: 4 | Y5: المندوب لم يكتب: Plot Number، مرفقات، Source، ملاحظات (4 خانة ناقصة)
A6: 43070 | B6: 2026-09-02 | C6: 10:59 | D6: Yossry Fayez | E6: Abu Dhabi, and Al Ain 1 | F6: Clients | G6: النشمي للاستشارات الهندسية- دلة البنيان | H6: النشمي للاستشارات | I6: نعم | K6: لا | L6: النشمي للاستشارت الهندسية | M6: نعم | N6: دلة البنيان للمقاولات العامة | O6: نعم | P6: مواقع | Q6: نعم | R6: 0 | S6: لا | T6: مكاتب | U6: نعم | V6: 0 | W6: لا | X6: 3 | Y6: المندوب لم يكتب: Plot Number، مرفقات، ملاحظات (3 خانة ناقصة)
A7: 43074 | B7: 2026-09-02 | C7: 13:04 | D7: Abdullhadi AlHariri | E7: Abu Dhabi, and Al Ain 1 | F7: Clients | G7: فرصة محمد الحارثي | H7: محمد الحارثي | I7: نعم | K7: لا | M7: لا | O7: لا | P7: مصعد | Q7: نعم | R7: 0 | S7: لا | U7: لا | V7: 24 | W7: نعم | X7: 5 | Y7: المندوب لم يكتب: Plot Number، الاستشاري، المقاول، مرفقات، Source (5 خانة ناقصة)
A8: 43075 | B8: 2026-09-02 | C8: 13:46 | D8: Abdullhadi AlHariri | E8: Abu Dhabi, and Al Ain 1 | F8: Clients | G8: فرصة ابوسلطان \\\\ خال بدر الكندي | H8: ابوسلطان \\\\ خال بدر الكندي | I8: نعم | K8: لا | M8: لا | O8: لا | Q8: لا | R8: 0 | S8: لا | U8: لا | V8: 0 | W8: لا | X8: 7 | Y8: المندوب لم يكتب: Plot Number، الاستشاري، المقاول، Tags، مرفقات، Source، ملاحظات (7 خانة ناقصة)
A9: 43076 | B9: 2026-09-02 | C9: 13:57 | D9: Abdullhadi AlHariri | E9: Abu Dhabi, and Al Ain 1 | F9: Clients | G9: فرصة محمد احمد بن عمرو | H9: محمد احمد بن عمرو | I9: نعم | K9: لا | L9: اركال | M9: نعم | N9: كيس ديا كواليتي | O9: نعم | P9: مصعد | Q9: نعم | R9: 0 | S9: لا | U9: لا | V9: 0 | W9: لا | X9: 4 | Y9: المندوب لم يكتب: Plot Number، مرفقات، Source، ملاحظات (4 خانة ناقصة)
A10: 43077 | B10: 2026-09-02 | C10: 14:02 | D10: Ahmed Alattar | E10: ADMIN | F10: Clients | G10: مكتب بلديانو للعقارات's opportunity | H10: مكتب بلديانو للعقارات | I10: نعم | K10: لا | M10: لا | O10: لا | P10: مكتب مقاولات | Q10: نعم | R10: 0 | S10: لا | U10: لا | V10: 37 | W10: نعم | X10: 5 | Y10: المندوب لم يكتب: Plot Number، الاستشاري، المقاول، مرفقات، Source (5 خانة ناقصة)
A11: 43078 | B11: 2026-09-02 | C11: 15:29 | D11: Yossry Fayez | E11: Abu Dhabi, and Al Ain 1 | F11: Clients | G11: النهضة الذهبية للمقاولات- سبوكس للاستثما | H11: النهضة الذهبية للمقاولات | I11: نعم | K11: لا | L11: رويال دوم للاستشارات الهندسية | M11: نعم | N11: النهضة الذهبية | O11: نعم | P11: عملاء مكاتب | Q11: نعم | R11: 0 | S11: لا | T11: مكاتب | U11: نعم | V11: 0 | W11: لا | X11: 3 | Y11: المندوب لم يكتب: Plot Number، مرفقات، ملاحظات (3 خانة ناقصة)
A12: 43081 | B12: 2026-09-02 | C12: 19:29 | D12: Mohammed Jamal | E12: Abu Dhabi, and Al Ain | F12: Clients | G12: لاميزون للمقاولات العامة's opportunity | H12: لاميزون للمقاولات العامة | I12: نعم | K12: لا | L12: كالتشر للاستشارات الهندسية | M12: نعم | O12: لا | P12: مواقع | Q12: نعم | R12: 0 | S12: لا | T12: مواقع | U12: نعم | V12: 0 | W12: لا | X12: 4 | Y12: المندوب لم يكتب: Plot Number، المقاول، مرفقات، ملاحظات (4 خانة ناقصة)
A13: 43082 | B13: 2026-09-02 | C13: 19:30 | D13: Mohammed Jamal | E13: Abu Dhabi, and Al Ain | F13: Clients | G13: الكفاءات للمقاولات العامة's opportunity | H13: الكفاءات للمقاولات العامة | I13: نعم | K13: لا | L13: فريد دزاين للاستشارات | M13: نعم | O13: لا | P13: مواقع | Q13: نعم | R13: 0 | S13: لا | T13: مواقع | U13: نعم | V13: 0 | W13: لا | X13: 4 | Y13: المندوب لم يكتب: Plot Number، المقاول، مرفقات، ملاحظات (4 خانة ناقصة)
A14: 43083 | B14: 2026-09-02 | C14: 19:32 | D14: Mohammed Jamal | E14: Abu Dhabi, and Al Ain | F14: Clients | G14: ايجبيان للمقاولات العامة's opportunity | H14: ايجبيان للمقاولات العامة | I14: نعم | K14: لا | L14: بارين للمقاولات العامة | M14: نعم | O14: لا | P14: مواقع | Q14: نعم | R14: 0 | S14: لا | T14: مواقع | U14: نعم | V14: 0 | W14: لا | X14: 4 | Y14: المندوب لم يكتب: Plot Number، المقاول، مرفقات، ملاحظات (4 خانة ناقصة)
A15: 43084 | B15: 2026-09-02 | C15: 19:33 | D15: Mohammed Jamal | E15: Abu Dhabi, and Al Ain | F15: Clients | G15: معرض العين's opportunity | H15: معرض العين | I15: نعم | K15: لا | M15: لا | O15: لا | Q15: لا | R15: 0 | S15: لا | U15: لا | V15: 0 | W15: لا | X15: 7 | Y15: المندوب لم يكتب: Plot Number، الاستشاري، المقاول، Tags، مرفقات، Source، ملاحظات (7 خانة ناقصة)
A16: 43088 | B16: 2026-09-03 | C16: 11:25 | D16: Yossry Fayez | E16: Abu Dhabi, and Al Ain 1 | F16: Quotation | G16: الوشاح الابيض للمقاولات العامة- مسلم عوض | H16: الوشاح الابيض للمقاولات العامة | I16: نعم | K16: لا | L16: مكتب ريفييرا للاستشارات الهندسية | M16: نعم | N16: مكتب الوشاح الأبيض للمقاولات | O16: نعم | P16: عملاء مكاتب | Q16: نعم | R16: 0 | S16: لا | T16: مكاتب | U16: نعم | V16: 0 | W16: لا | X16: 3 | Y16: المندوب لم يكتب: Plot Number، مرفقات، ملاحظات (3 خانة ناقصة)
A17: 43099 | B17: 2026-09-03 | C17: 19:15 | D17: Mohammed Jamal | E17: Abu Dhabi, and Al Ain | F17: Clients | G17: معرض العين's opportunity | H17: معرض العين | I17: نعم | K17: لا | M17: لا | O17: لا | P17: مواقع | Q17: نعم | R17: 0 | S17: لا | T17: معرض | U17: نعم | V17: 0 | W17: لا | X17: 5 | Y17: المندوب لم يكتب: Plot Number، الاستشاري، المقاول، مرفقات، ملاحظات (5 خانة ناقصة)
A18: 43100 | B18: 2026-09-03 | C18: 23:14 | D18: Ahmed Alattar | E18: ADMIN | F18: Clients | G18: مكتب جلف هيلز للمقاولات's opportunity | H18: مكتب جلف هيلز للمقاولات | I18: نعم | K18: لا | M18: لا | N18: جلف هيلز للمقاولات | O18: نعم | P18: مكتب مقاولات | Q18: نعم | R18: 0 | S18: لا | U18: لا | V18: 0 | W18: لا | X18: 5 | Y18: المندوب لم يكتب: Plot Number، الاستشاري، مرفقات، Source، ملاحظات (5 خانة ناقصة)
A19: 43101 | B19: 2026-09-03 | C19: 23:22 | D19: Ahmed Alattar | E19: ADMIN | F19: Clients | G19: مكتب اليزان للمقاولات | H19: اليزان للمقاولات | I19: نعم | K19: لا | M19: لا | N19: اليزان للمقاولات العامة | O19: نعم | P19: مكتب مقاولات | Q19: نعم | R19: 0 | S19: لا | U19: لا | V19: 0 | W19: لا | X19: 5 | Y19: المندوب لم يكتب: Plot Number، الاستشاري، مرفقات، Source، ملاحظات (5 خانة ناقصة)
A20: 43102 | B20: 2026-09-03 | C20: 23:26 | D20: Ahmed Alattar | E20: ADMIN | F20: Clients | G20: مكتب ذا بلو ابل للاستشارات والمقاولات's | H20: مكتب ذا بلو ابل للاستشارات والمقاولات | I20: نعم | K20: لا | L20: ذا بلو ابل للاستشارات | M20: نعم | N20: ذا بلو ابل للمقاولات | O20: نعم | P20: مكتب استشارات, مكتب مقاولات | Q20: نعم | R20: 0 | S20: لا | U20: لا | V20: 23 | W20: نعم | X20: 3 | Y20: المندوب لم يكتب: Plot Number، مرفقات، Source (3 خانة ناقصة)
A21: 43103 | B21: 2026-09-03 | C21: 23:34 | D21: Ahmed Alattar | E21: ADMIN | F21: Clients | G21: مكتب تكنوميك's opportunity | H21: مكتب تكنوميك | I21: نعم | K21: لا | M21: لا | N21: تكنوميك للمقاولات | O21: نعم | P21: مكتب مقاولات | Q21: نعم | R21: 0 | S21: لا | U21: لا | V21: 36 | W21: نعم | X21: 4 | Y21: المندوب لم يكتب: Plot Number، الاستشاري، مرفقات، Source (4 خانة ناقصة)
A22: 43104 | B22: 2026-09-04 | C22: 22:18 | D22: Abdullhadi AlHariri | E22: Abu Dhabi, and Al Ain 1 | F22: Won | G22: فرصة بدر الكندي | H22: بدر الكندي | I22: نعم | J22: ١ | K22: نعم | L22: المؤيد | M22: نعم | N22: اسناد الخليج | O22: نعم | P22: متعاقد, مصعد | Q22: نعم | R22: 0 | S22: لا | U22: لا | V22: 0 | W22: لا | X22: 3 | Y22: المندوب لم يكتب: مرفقات، Source، ملاحظات (3 خانة ناقصة)
A23: 43105 | B23: 2026-09-04 | C23: 22:45 | D23: Abdullhadi AlHariri | E23: Abu Dhabi, and Al Ain 1 | F23: Clients | G23: ام احمد حصه | H23: ام احمد حصه | I23: نعم | K23: لا | M23: لا | O23: لا | P23: مصعد | Q23: نعم | R23: 0 | S23: لا | U23: لا | V23: 0 | W23: لا | X23: 6 | Y23: المندوب لم يكتب: Plot Number، الاستشاري، المقاول، مرفقات، Source، ملاحظات (6 خانة ناقصة)
A24: 43106 | B24: 2026-09-05 | C24: 10:18 | D24: Yossry Fayez | E24: Abu Dhabi, and Al Ain 1 | F24: Clients | G24: سكاي للانشاءات- عبدالحكيم الزبيدي | H24: سكاي للانشاءات | I24: نعم | K24: لا | L24: قواعد للاستشارات الهندسيه | M24: نعم | N24: سكاي للانشاءات | O24: نعم | P24: مصعد, مواقع, سمارت هوم | Q24: نعم | R24: 0 | S24: لا | T24: مواقع | U24: نعم | V24: 0 | W24: لا | X24: 3 | Y24: المندوب لم يكتب: Plot Number، مرفقات، ملاحظات (3 خانة ناقصة)
A25: 43107 | B25: 2026-09-05 | C25: 12:06 | D25: Yossry Fayez | E25: Abu Dhabi, and Al Ain 1 | F25: Clients | G25: كابلرز للمقاولات العامة- ام بي اي للاستش | H25: كابلرز للمقاولات العامة | I25: نعم | K25: لا | L25: مكتب ام بي اي للاستشارات الهندسي | M25: نعم | N25: كابلرز | O25: نعم | P25: مصعد, مواقع | Q25: نعم | R25: 0 | S25: لا | T25: مواقع | U25: نعم | V25: 0 | W25: لا | X25: 3 | Y25: المندوب لم يكتب: Plot Number، مرفقات، ملاحظات (3 خانة ناقصة)
A26: 43108 | B26: 2026-09-05 | C26: 12:13 | D26: Yossry Fayez | E26: Abu Dhabi, and Al Ain 1 | F26: Clients | G26: اونكس للاستشارات- للاستشارات- توليدو للم | H26: اونكس للاستشارات | I26: نعم | K26: لا | L26: اونكس للاستشارات الهندسية | M26: نعم | N26: توليدو للمقاولات العامة | O26: نعم | Q26: لا | R26: 0 | S26: لا | T26: مواقع | U26: نعم | V26: 0 | W26: لا | X26: 4 | Y26: المندوب لم يكتب: Plot Number، Tags، مرفقات، ملاحظات (4 خانة ناقصة)
A27: 43116 | B27: 2026-09-05 | C27: 15:29 | D27: Ahmed Salah | E27: Abu Dhabi, and Al Ain 1 | F27: Clients | G27: محمد بخيت سهيل الراشدي | I27: لا | K27: لا | M27: لا | O27: لا | Q27: لا | R27: 0 | S27: لا | U27: لا | V27: 0 | W27: لا | X27: 8 | Y27: المندوب لم يكتب: اسم العميل، Plot Number، الاستشاري، المقاول، Tags، مرفقات، Source، ملاحظات (8 خانة ناقصة)
A28: 43118 | B28: 2026-09-05 | C28: 16:02 | D28: Ahmed Alattar | E28: ADMIN | F28: Clients | G28: مكتب ديار عجمان للمقاولات's opportunity | H28: مكتب ديار عجمان للمقاولات | I28: نعم | K28: لا | M28: لا | N28: ديار عجمان للمقاولات | O28: نعم | P28: مكتب مقاولات | Q28: نعم | R28: 0 | S28: لا | U28: لا | V28: 0 | W28: لا | X28: 5 | Y28: المندوب لم يكتب: Plot Number، الاستشاري، مرفقات، Source، ملاحظات (5 خانة ناقصة)
A29: 43119 | B29: 2026-09-05 | C29: 16:30 | D29: Mohammed Jamal | E29: Abu Dhabi, and Al Ain | F29: Clients | G29: العصر الفضي للمقاولات's opportunity | H29: العصر الفضي للمقاولات | I29: نعم | K29: لا | L29: البحري للاستشارات الهندسية | M29: نعم | N29: العصر الفضي للمقاولات | O29: نعم | P29: مواقع | Q29: نعم | R29: 0 | S29: لا | T29: مواقع | U29: نعم | V29: 0 | W29: لا | X29: 3 | Y29: المندوب لم يكتب: Plot Number، مرفقات، ملاحظات (3 خانة ناقصة)
A30: 43120 | B30: 2026-09-05 | C30: 16:32 | D30: Mohammed Jamal | E30: Abu Dhabi, and Al Ain | F30: Clients | G30: الكواكب للمقاولات العامة's opportunity | H30: الكواكب للمقاولات العامة | I30: نعم | K30: لا | M30: لا | O30: لا | P30: مواقع | Q30: نعم | R30: 0 | S30: لا | T30: مواقع | U30: نعم | V30: 0 | W30: لا | X30: 5 | Y30: المندوب لم يكتب: Plot Number، الاستشاري، المقاول، مرفقات، ملاحظات (5 خانة ناقصة)
A31: 43121 | B31: 2026-09-05 | C31: 16:34 | D31: Mohammed Jamal | E31: Abu Dhabi, and Al Ain | F31: Clients | G31: تلال الغدير للمقاولات's opportunity | H31: تلال الغدير للمقاولات | I31: نعم | K31: لا | M31: لا | O31: لا | Q31: لا | R31: 0 | S31: لا | U31: لا | V31: 0 | W31: لا | X31: 7 | Y31: المندوب لم يكتب: Plot Number، الاستشاري، المقاول، Tags، مرفقات، Source، ملاحظات (7 خانة ناقصة)
A32: 43122 | B32: 2026-09-05 | C32: 16:34 | D32: Mohammed Jamal | E32: Abu Dhabi, and Al Ain | F32: Clients | G32: تلال الغدير للمقاولات's opportunity | H32: تلال الغدير للمقاولات | I32: نعم | K32: لا | L32: ديماس للاستشارات الهندسية | M32: نعم | O32: لا | P32: مواقع | Q32: نعم | R32: 0 | S32: لا | T32: مواقع | U32: نعم | V32: 0 | W32: لا | X32: 4 | Y32: المندوب لم يكتب: Plot Number، المقاول، مرفقات، ملاحظات (4 خانة ناقصة)
A33: 43123 | B33: 2026-09-05 | C33: 16:38 | D33: Mohammed Jamal | E33: Abu Dhabi, and Al Ain | F33: Clients | G33: التميز الهندسي للمقاولات العامة's opport | H33: التميز الهندسي للمقاولات العامة | I33: نعم | K33: لا | L33: اركال للاستشارات الهندسية | M33: نعم | N33: التميز الهندسي للمقاولات | O33: نعم | P33: مواقع | Q33: نعم | R33: 0 | S33: لا | T33: مواقع | U33: نعم | V33: 0 | W33: لا | X33: 3 | Y33: المندوب لم يكتب: Plot Number، مرفقات، ملاحظات (3 خانة ناقصة)
A34: 43124 | B34: 2026-09-05 | C34: 16:42 | D34: Abdullhadi AlHariri | E34: Abu Dhabi, and Al Ain 1 | F34: Clients | G34: ابراهيم بن عيسي العلي | H34: ابراهيم بن عيسي العلي | I34: نعم | K34: لا | L34: الامل | M34: نعم | O34: لا | P34: معرض, مصعد | Q34: نعم | R34: 0 | S34: لا | U34: لا | V34: 0 | W34: لا | X34: 5 | Y34: المندوب لم يكتب: Plot Number، المقاول، مرفقات، Source، ملاحظات (5 خانة ناقصة)
A35: 43126 | B35: 2026-09-05 | C35: 16:45 | D35: Ramy Moussa | E35: Abu Dhabi, and Al Ain | F35: Clients | G35: مؤسسه البحث للمقاولات's opportunity | H35: مؤسسه البحث للمقاولات | I35: نعم | K35: لا | M35: لا | O35: لا | Q35: لا | R35: 0 | S35: لا | U35: لا | V35: 0 | W35: لا | X35: 7 | Y35: المندوب لم يكتب: Plot Number، الاستشاري، المقاول، Tags، مرفقات، Source، ملاحظات (7 خانة ناقصة)
A36: 43127 | B36: 2026-09-05 | C36: 16:46 | D36: Ramy Moussa | E36: Abu Dhabi, and Al Ain | F36: Clients | G36: عبدالله مصبح الكعبي's opportunity | H36: عبدالله مصبح الكعبي | I36: نعم | K36: لا | M36: لا | O36: لا | Q36: لا | R36: 0 | S36: لا | U36: لا | V36: 0 | W36: لا | X36: 7 | Y36: المندوب لم يكتب: Plot Number، الاستشاري، المقاول، Tags، مرفقات، Source، ملاحظات (7 خانة ناقصة)
A37: 43129 | B37: 2026-09-05 | C37: 17:04 | D37: Yossry Fayez | E37: Abu Dhabi, and Al Ain 1 | F37: Quotation | G37: هيفين للمقاولات العامة- عباس درويش لاري | H37: هيفين للمقاولات العامة | I37: نعم | K37: لا | M37: لا | N37: هيفين للمقاولات العامة | O37: نعم | P37: مصعد, عملاء مكاتب | Q37: نعم | R37: 0 | S37: لا | T37: مواقع | U37: نعم | V37: 0 | W37: لا | X37: 4 | Y37: المندوب لم يكتب: Plot Number، الاستشاري، مرفقات، ملاحظات (4 خانة ناقصة)
A38: 43130 | B38: 2026-09-05 | C38: 21:12 | D38: Ahmed Alattar | E38: ADMIN | F38: Clients | G38: مكتب الحوتى للمقاولات's opportunity | H38: مكتب الحوتى للمقاولات | I38: نعم | K38: لا | M38: لا | N38: الحوتى للمقاولات | O38: نعم | P38: مكتب مقاولات | Q38: نعم | R38: 0 | S38: لا | U38: لا | V38: 0 | W38: لا | X38: 5 | Y38: المندوب لم يكتب: Plot Number، الاستشاري، مرفقات، Source، ملاحظات (5 خانة ناقصة)
A39: 43155 | B39: 2026-09-06 | C39: 19:48 | D39: Mohammed Jamal | E39: Abu Dhabi, and Al Ain | F39: Clients | G39: الدوام اليوم | I39: لا | K39: لا | M39: لا | O39: لا | P39: مكتب | Q39: نعم | R39: 0 | S39: لا | U39: لا | V39: 0 | W39: لا | X39: 7 | Y39: المندوب لم يكتب: اسم العميل، Plot Number، الاستشاري، المقاول، مرفقات، Source، ملاحظات (7 خانة ناقصة)
A40: 43167 | B40: 2026-09-07 | C40: 11:30 | D40: Mohamed Saqr | E40: Abu Dhabi, and Al Ain | F40: Clients | G40: حمد الهاجري | I40: لا | K40: لا | M40: لا | O40: لا | Q40: لا | R40: 0 | S40: لا | U40: لا | V40: 0 | W40: لا | X40: 8 | Y40: المندوب لم يكتب: اسم العميل، Plot Number، الاستشاري، المقاول، Tags، مرفقات، Source، ملاحظات (8 خانة ناقصة)
...

Sheet سجل الأكشنات
A1: رقم الفرصة | B1: التاريخ | C1: الوقت | D1: المندوب | E1: نوع السجل | F1: نوع النشاط | G1: عدد الحروف | H1: مستوى التفاصيل | I1: نص الأكشن (أول ٥٠ حرف) | J1: الملاحظة
A2: 43054 | B2: 2026-09-01 | C2: 09:58 | D2: Yossry Fayez | E2: نشاط منفذ | F2: Site Visit | G2: 117 | H2: تفصيلي | I2: تم زيارة الموقع في مرحلة الخرسانة ويوجد مصعد وتم ا | J2: أكشن مكتوب بتفاصيل كافية ✔
A3: 33472 | B3: 2026-09-01 | C3: 10:21 | D3: Yossry Fayez | E3: نشاط منفذ | F3: Meeting | G3: 96 | H3: تفصيلي | I3: تم زيارة المكتب ومقابلة المدير وتم مناقشة احد المش | J3: أكشن مكتوب بتفاصيل كافية ✔
A4: 43060 | B4: 2026-09-01 | C4: 11:09 | D4: Yossry Fayez | E4: نشاط منفذ | F4: Site Visit | G4: 147 | H4: تفصيلي | I4: تم زيار ة الموقع ومقابلة المقاول وهو نفسه المالك و | J4: أكشن مكتوب بتفاصيل كافية ✔
A5: 38433 | B5: 2026-09-01 | C5: 11:29 | D5: Yossry Fayez | E5: نشاط منفذ | F5: Site Visit | G5: 94 | H5: تفصيلي | I5: تم زيارة الموقع للمتابعة والمشروع شبه متوقف وتم ال | J5: أكشن مكتوب بتفاصيل كافية ✔
A6: 41401 | B6: 2026-09-01 | C6: 11:42 | D6: Abdullhadi AlHariri | E6: نشاط منفذ | F6: Meeting | G6: 87 | H6: تفصيلي | I6: الاجتماع تم : تم التواصل واتس اب والاستفسار عن سما | J6: أكشن مكتوب بتفاصيل كافية ✔
A7: 29106 | B7: 2026-09-01 | C7: 11:56 | D7: Yossry Fayez | E7: نشاط منفذ | F7: Meeting | G7: 66 | H7: تفصيلي | I7: تم زيارة المكتب ومقابلة السكريتير وقال المدير مساف | J7: أكشن مكتوب بتفاصيل كافية ✔
A8: 29111 | B8: 2026-09-01 | C8: 11:58 | D8: Yossry Fayez | E8: نشاط منفذ | F8: Meeting | G8: 73 | H8: تفصيلي | I8: تم زيارة المكتب ومقابلة المنندس عمر وقال مهندس محم | J8: أكشن مكتوب بتفاصيل كافية ✔
A9: 41288 | B9: 2026-09-01 | C9: 13:36 | D9: Yossry Fayez | E9: نشاط منفذ | F9: Call | G9: 87 | H9: تفصيلي | I9: تم الاتصال بمكتب الاستشاري وقال لسه المطورن موقف ا | J9: أكشن مكتوب بتفاصيل كافية ✔
A10: 40733 | B10: 2026-09-01 | C10: 14:07 | D10: Hossam Radi | E10: نشاط منفذ | F10: WhatsApp | G10: 127 | H10: تفصيلي | I10: WhatsApp done Original note: تم النتهاء من التؤكيب | J10: أكشن مكتوب بتفاصيل كافية ✔
A11: 41505 | B11: 2026-09-01 | C11: 14:09 | D11: Hossam Radi | E11: نشاط منفذ | F11: Call | G11: 143 | H11: تفصيلي | I11: Call done Original note: تم التواصل والمتابعه وقال | J11: أكشن مكتوب بتفاصيل كافية ✔
A12: 40522 | B12: 2026-09-01 | C12: 14:12 | D12: Hossam Radi | E12: نشاط منفذ | F12: Call | G12: 61 | H12: تفصيلي | I12: Call done Original note: تم التواصل ولم يرد وسيت م | J12: أكشن مكتوب بتفاصيل كافية ✔
A13: 38443 | B13: 2026-09-01 | C13: 14:14 | D13: Hossam Radi | E13: نشاط منفذ | F13: To Do | G13: 69 | H13: تفصيلي | I13: To Do done Original note: تم دفع 5000 ودا الايصال | J13: أكشن مكتوب بتفاصيل كافية ✔
... A35: 40549 | B35: 2026-09-02 | C35: 10:06 | D35: Yossry Fayez | E35: نشاط منفذ | F35: Site Visit | G35: 81 | H35: تفصيلي | I35: تم زيارة الموقع للتاكد من جاهزية الموقع ولكن الباي | J35: أكشن مكتوب بتفاصيل كافية ✔
A36: 40549 | B36: 2026-09-02 | C36: 10:06 | D36: Yossry Fayez | E36: ملاحظة | G36: 0 | H36: مختصر جداً / فارغ | J36: ملاحظة مسجّلة بدون أي نص
A37: 38089 | B37: 2026-09-02 | C37: 10:36 | D37: Yossry Fayez | E37: نشاط منفذ | F37: Site Visit | G37: 136 | H37: تفصيلي | I37: تم زيارة الموقع لمتابعة عروض الاسعار وتم توقيع عقد | J37: أكشن مكتوب بتفاصيل كافية ✔
A38: 43070 | B38: 2026-09-02 | C38: 11:01 | D38: Yossry Fayez | E38: نشاط منفذ | F38: Site Visit | G38: 83 | H38: تفصيلي | I38: تم زيارة الموقع في مرحلة الاساسات وتم الاتصال بالم | J38: أكشن مكتوب بتفاصيل كافية ✔
A39: 25129 | B39: 2026-09-02 | C39: 12:30 | D39: Yossry Fayez | E39: نشاط منفذ | F39: Call | G39: 71 | H39: تفصيلي | I39: تم الاتصال من المالك طلب اجتماع غدا بالموقع لمقابل | J39: أكشن مكتوب بتفاصيل كافية ✔
A40: 40498 | B40: 2026-09-02 | C40: 13:04 | D40: Yossry Fayez | E40: نشاط منفذ | F40: Call | G40: 138 | H40: تفصيلي | I40: تم الاتصال بالمالك وقال محتاج يعمل معاينة لمصعد فو | J40: أكشن مكتوب بتفاصيل كافية ✔
A41: 40498 | B41: 2026-09-02 | C41: 13:04 | D41: Yossry Fayez | E41: نشاط منفذ | F41: To Do | G41: 10 | H41: مختصر جداً / فارغ | I41: To Do done | J41: أكشن مختصر جداً — النص تلقائي/عام بدون تفاصيل الزيارة أو نتيجتها
A42: 43074 | B42: 2026-09-02 | C42: 13:09 | D42: Abdullhadi AlHariri | E42: نشاط منفذ | F42: Meeting | G42: 99 | H42: تفصيلي | I42: الاجتماع تم : عميل من داتا استاذ فراس تم التواصل و | J42: أكشن مكتوب بتفاصيل كافية ✔
A43: 39518 | B43: 2026-09-02 | C43: 13:11 | D43: Ahmed Salah | E43: نشاط منفذ | F43: Meeting | G43: 55 | H43: تفصيلي | I43: الاجتماع تم : تمت زياره للمكتب وعدم تواجد م حسن وم | J43: أكشن مكتوب بتفاصيل كافية ✔
A44: 40688 | B44: 2026-09-02 | C44: 13:13 | D44: Ahmed Salah | E44: نشاط منفذ | F44: Meeting | G44: 116 | H44: تفصيلي | I44: الاجتماع تم : تمت زياره للمكتب ومقابله م ياسر ومنا | J44: أكشن مكتوب بتفاصيل كافية ✔
A45: 40608 | B45: 2026-09-02 | C45: 13:17 | D45: Ahmed Salah | E45: نشاط منفذ | F45: Meeting | G45: 208 | H45: تفصيلي | I45: الاجتماع تم : تمت زياره للمكتب لمتابعه التحصيل وعم | J45: أكشن مكتوب بتفاصيل كافية ✔
A46: 43075 | B46: 2026-09-02 | C46: 13:48 | D46: Abdullhadi AlHariri | E46: نشاط منفذ | F46: Meeting | G46: 163 | H46: تفصيلي | I46: الاجتماع تم : عميل خال العميل بدر الكندي بيستفسر ع | J46: أكشن مكتوب بتفاصيل كافية ✔
A47: 40310 | B47: 2026-09-02 | C47: 13:49 | D47: Abdullhadi AlHariri | E47: نشاط منفذ | F47: Meeting | G47: 93 | H47: تفصيلي | I47: الاجتماع تم : تم زياره الموقع اليوم لمتابعه الموقع | J47: أكشن مكتوب بتفاصيل كافية ✔
A48: 41401 | B48: 2026-09-02 | C48: 13:52 | D48: Abdullhadi AlHariri | E48: نشاط منفذ | F48: Meeting | G48: 184 | H48: تفصيلي | I48: الاجتماع تم : تم زياره الموقع ومقابله المقاول لمتا | J48: أكشن مكتوب بتفاصيل كافية ✔
... A58: 43088 | B58: 2026-09-03 | C58: 11:29 | D58: Yossry Fayez | E58: نشاط منفذ | F58: Site Visit | G58: 78 | H58: تفصيلي | I58: تم التواصل مع المقاول بالواتس اب وارسل مخطط مصعد و | J58: أكشن مكتوب بتفاصيل كافية ✔
A59: 43088 | B59: 2026-09-03 | C59: 11:30 | D59: Yossry Fayez | E59: ملاحظة | G59: 0 | H59: مختصر جداً / فارغ | J59: ملاحظة مسجّلة بدون أي نص
A60: 42637 | B60: 2026-09-03 | C60: 11:49 | D60: Hossam Radi | E60: نشاط منفذ | F60: Meeting | G60: 198 | H60: تفصيلي | I60: المالك طارق الكثيري - معرض - 8 - 2026 تم التواصل و | J60: أكشن مكتوب بتفاصيل كافية ✔
A61: 42634 | B61: 2026-09-03 | C61: 11:50 | D61: Hossam Radi | E61: نشاط منفذ | F61: To Do | G61: 63 | H61: تفصيلي | I61: To Do done Original note: تم التواصل ومتابعه وف ان | J61: أكشن مكتوب بتفاصيل كافية ✔
A62: 42946 | B62: 2026-09-03 | C62: 11:53 | D62: Hossam Radi | E62: نشاط منفذ | F62: Call | G62: 85 | H62: تفصيلي | I62: Call done Original note: تم التواصل ولم ىيرد وسيتم | J62: أكشن مكتوب بتفاصيل كافية ✔
A63: 42954 | B63: 2026-09-03 | C63: 11:54 | D63: Hossam Radi | E63: نشاط منفذ | F63: To Do | G63: 96 | H63: تفصيلي | I63: To Do done Original note: تم التواصل ولم يرد وسيتم | J63: أكشن مكتوب بتفاصيل كافية ✔
A64: 40688 | B64: 2026-09-03 | C64: 12:42 | D64: Ahmed Salah | E64: نشاط منفذ | F64: Meeting | G64: 93 | H64: تفصيلي | I64: الاجتماع تم : تمت زياره للمكتب ومقابله م ياسر وتسل | J64: أكشن مكتوب بتفاصيل كافية ✔
A65: 40742 | B65: 2026-09-03 | C65: 12:44 | D65: Ahmed Salah | E65: نشاط منفذ | F65: Meeting | G65: 109 | H65: تفصيلي | I65: الاجتماع تم : تمت زياره للمكتب ومقابله ابوسلطان وم | J65: أكشن مكتوب بتفاصيل كافية ✔
A66: 41583 | B66: 2026-09-03 | C66: 15:19 | D66: Ahmed Salah | E66: نشاط منفذ | F66: Meeting | G66: 125 | H66: تفصيلي | I66: الاجتماع تم : تمت زياره للمكتب وعدم تواجد م محمد و | J66: أكشن مكتوب بتفاصيل كافية ✔
A67: 40608 | B67: 2026-09-03 | C67: 15:22 | D67: Ahmed Salah | E67: نشاط منفذ | F67: Call | G67: 94 | H67: تفصيلي | I67: مكالمة تم : تم التواصل مع المهندس والمحاسب لتحصيل | J67: أكشن مكتوب بتفاصيل كافية ✔
A68: 43099 | B68: 2026-09-03 | C68: 19:18 | D68: Mohammed Jamal | E68: نشاط منفذ | F68: Meeting | G68: 138 | H68: تفصيلي | I68: الدوام من المعرض لمتابعة عروض الاسعار .. وتم مقابل | J68: أكشن مكتوب بتفاصيل كافية ✔
A69: 43100 | B69: 2026-09-03 | C69: 23:16 | D69: Ahmed Alattar | E69: نشاط منفذ | F69: Meeting | G69: 59 | H69: تفصيلي | I69: تم مقابلة مهندسة ايمان وسيتم ارسال مشروع لتسعير ال | J69: أكشن مكتوب بتفاصيل كافية ✔
A70: 42457 | B70: 2026-09-03 | C70: 23:19 | D70: Ahmed Alattar | E70: نشاط منفذ | F70: Meeting | G70: 80 | H70: تفصيلي | I70: تم مقابلة صاحب الشركة والمهندس المسؤول عن الموقع.. | J70: أكشن مكتوب بتفاصيل كافية ✔
...
